<?xml version="1.0"?>
<robot xmlns:xacro="http://www.ros.org/wiki/xacro">

<!-- ODE joint motor macro -->
<xacro:macro name="joint_motor" params="motor_name parent_link child_link *origin">

  <!-- <xacro:property name="params_yaml"  value="$(find nowtech_actuator_models)/params/joint_motor.yaml"/> -->
  <xacro:property name="motor_param"  value="${load_yaml(params_yaml)}"/>

  <joint name="${motor_name}" type="continuous">
      <parent link="${parent_link}"/>
      <child link="${child_link}"/>
      <xacro:insert_block name="origin"/>
      <axis xyz="0 0 1"/>
      <dynamics damping="${motor_param['joint_damping']}" friction="${motor_param['joint_friction']}"/>
  </joint>

  <gazebo>
    <plugin name="motor_plugin" filename="libnowtech_gazebo_ros_joint_motor.so">
      <command_topic>${motor_name}/command</command_topic>
      <velocity_topic>${motor_name}/velocity</velocity_topic>
      <encoder_topic>${motor_name}/encoder</encoder_topic>
      <motor_shaft_joint>${motor_name}</motor_shaft_joint>
      <motor_wrench_frame>${child_link}</motor_wrench_frame>
      <ode_joint_motor_fmax>${motor_param['ode_joint_motor_fmax']}</ode_joint_motor_fmax>
      <ode_joint_fudge_factor>${motor_param['ode_joint_fudge_factor']}</ode_joint_fudge_factor>
      <publish_velocity>${motor_param['publish_velocity']}</publish_velocity>
      <publish_encoder>${motor_param['publish_encoder']}</publish_encoder>
      <publish_motor_joint_state>${motor_param['publish_motor_joint_state']}</publish_motor_joint_state>
      <update_rate>${motor_param['update_rate']}</update_rate>
      <encoder_ppr>${motor_param['encoder_ppr']}</encoder_ppr>
      <encoder_to_shaft_ratio>${motor_param['encoder_to_shaft_ratio']}</encoder_to_shaft_ratio>
      <rosDebugLevel>Debug</rosDebugLevel>
    </plugin>
  </gazebo>

</xacro:macro>


<!-- EMDC motor macro -->
<xacro:macro name="dc_motor" params="motor_name parent_link child_link *origin">
  <!-- <xacro:property name="params_yaml" value="$(find gazebo_ros_motors)/params/dc_motor.yaml"/> -->
  <xacro:property name="motor_param" value="${load_yaml(params_yaml)}"/>
  <joint name="${motor_name}" type="continuous">
      <parent link="${parent_link}"/>
      <child link="${child_link}"/>
      <xacro:insert_block name="origin"/>
      <axis xyz="0 0 1"/>
      <dynamics damping="${motor_param['joint_damping']}" friction="${motor_param['joint_friction']}"/>
  </joint>

  <gazebo reference="${motor_name}">
    <provideFeedback>true</provideFeedback>
  </gazebo>

  <gazebo>
    <plugin name="${motor_name}_ft_sensor" filename="libgazebo_ros_ft_sensor.so">
       <updateRate>100.0</updateRate>
       <topicName>${motor_name}/force_sensor</topicName>
       <jointName>${motor_name}</jointName>
     </plugin>
  </gazebo>

  <gazebo>
    <plugin name="${motor_name}" filename="libnowtech_gazebo_ros_dc_motor.so">
      <motor_shaft_joint>${motor_name}</motor_shaft_joint>
      <motor_wrench_frame>${child_link}</motor_wrench_frame>

      <command_topic>${motor_name}/voltage_norm</command_topic>
      <velocity_topic>${motor_name}/velocity</velocity_topic>
      <encoder_topic>${motor_name}/encoder</encoder_topic>
      <current_topic>${motor_name}/current</current_topic>
      <supply_topic>${motor_name}/supply_voltage</supply_topic>

      <publish_encoder>${motor_param['publish_encoder']}</publish_encoder>
      <publish_velocity>${motor_param['publish_velocity']}</publish_velocity>
      <publish_current>${motor_param['publish_current']}</publish_current>
      <publish_motor_joint_state>${motor_param['publish_motor_joint_state']}</publish_motor_joint_state>

      <update_rate>${motor_param['update_rate']}</update_rate>
      <motor_nominal_voltage>${motor_param['motor_nominal_voltage']}</motor_nominal_voltage>
      <moment_of_inertia>${motor_param['moment_of_inertia']}</moment_of_inertia>
      <armature_damping_ratio>${motor_param['armature_damping_ratio']}</armature_damping_ratio>
      <electromotive_force_constant>${motor_param['electromotive_force_constant']}</electromotive_force_constant>
      <electric_resistance>${motor_param['electric_resistance']}</electric_resistance>
      <electric_inductance>${motor_param['electric_inductance']}</electric_inductance>
      <gear_ratio>${motor_param['gear_ratio']}</gear_ratio>
      <encoder_ppr>${motor_param['encoder_ppr']}</encoder_ppr>
      <velocity_noise>${motor_param['velocity_noise']}</velocity_noise>
      <rosDebugLevel>Debug</rosDebugLevel>

    </plugin>
  </gazebo>

</xacro:macro>

</robot>
